Workbook

Sheet Summary
A1: Ophthalmology Vocabulary Reference – Doctor–Patient Conversations
A2: Eye-specific terms for diseases, diagnosis, medicines, procedures, and patient communication (Indian OPD context).
A4: Sheet | B4: What It Contains | C4: No. of Terms
A5: Diseases & Conditions | B5: Primary vocabulary of eye diseases and diagnosed conditions, grouped by anatomical category. | C5: =COUNTA('Diseases & Conditions'!A:A)-1 -> 157
A6: Symptoms & Complaints | B6: Chief complaints as patients say them, mapped to medical terms and history-taking questions. | C6: =COUNTA('Symptoms & Complaints'!A:A)-1 -> 48
A7: Examination & Tests | B7: Clinical examinations and investigations used to reach a diagnosis, with normal values. | C7: =COUNTA('Examination & Tests'!A:A)-1 -> 72
A8: Clinical Signs | B8: Examination findings doctors dictate or write in notes, and what they suggest. | C8: =COUNTA('Clinical Signs'!A:A)-1 -> 59
A9: Medicines | B9: Topical, systemic and intravitreal drugs used in ophthalmology with typical dosing as written on prescriptions. | C9: =COUNTA(Medicines!A:A)-1 -> 116
A10: Procedures & Surgery | B10: Surgeries, lasers, minor procedures and IOL types discussed with patients. | C10: =COUNTA('Procedures & Surgery'!A:A)-1 -> 64
A11: Optical & Refraction | B11: Spectacle, contact lens and refraction vocabulary used by optometrists and doctors. | C11: =COUNTA('Optical & Refraction'!A:A)-1 -> 37
A12: Rx Abbreviations | B12: Short forms used in OPD notes, case sheets and prescriptions. | C12: =COUNTA('Rx Abbreviations'!A:A)-1 -> 89
A13: Counselling & Advice | B13: Standard patient-facing phrases for drop use, surgery, and disease-specific advice. | C13: =COUNTA('Counselling & Advice'!A:A)-1 -> 54
A14: Eye Anatomy | B14: Anatomical terms that appear in diagnoses and explanations to patients. | C14: =COUNTA('Eye Anatomy'!A:A)-1 -> 50
A15: Conversation Scenarios | B15: End-to-end doctor–patient scenarios linking complaint → exam → diagnosis → prescription → advice. | C15: =COUNTA('Conversation Scenarios'!A:A)-1 -> 28
A16: Total terms | C16: =SUM(C5:C15) -> 774
A18: Disease Category | C18: Count
A19: Lens / Cataract | C19: =COUNTIF('Diseases & Conditions'!C:C,A19) -> 16
A20: Glaucoma | C20: =COUNTIF('Diseases & Conditions'!C:C,A20) -> 18
A21: Conjunctiva | C21: =COUNTIF('Diseases & Conditions'!C:C,A21) -> 16
A22: Ocular Surface | C22: =COUNTIF('Diseases & Conditions'!C:C,A22) -> 2
A23: Cornea | C23: =COUNTIF('Diseases & Conditions'!C:C,A23) -> 17
A24: Eyelid | C24: =COUNTIF('Diseases & Conditions'!C:C,A24) -> 16
A25: Lacrimal | C25: =COUNTIF('Diseases & Conditions'!C:C,A25) -> 5
A26: Uvea | C26: =COUNTIF('Diseases & Conditions'!C:C,A26) -> 8
A27: Sclera | C27: =COUNTIF('Diseases & Conditions'!C:C,A27) -> 2
A28: Retina | C28: =COUNTIF('Diseases & Conditions'!C:C,A28) -> 20
A29: Vitreous | C29: =COUNTIF('Diseases & Conditions'!C:C,A29) -> 3
A30: Neuro-ophthalmology | C30: =COUNTIF('Diseases & Conditions'!C:C,A30) -> 10
... A35: Other | C35: =COUNTIF('Diseases & Conditions'!C:C,A35) -> 2
A37: Medicine Group (Drug Class contains) | C37: Count
A38: Antibiotic | C38: =COUNTIF(Medicines!C:C,"*"&A38&"*") -> 21
A39: Antifungal | C39: =COUNTIF(Medicines!C:C,"*"&A39&"*") -> 4
A40: Antiviral | C40: =COUNTIF(Medicines!C:C,"*"&A40&"*") -> 4
A41: Corticosteroid | C41: =COUNTIF(Medicines!C:C,"*"&A41&"*") -> 10
A42: NSAID | C42: =COUNTIF(Medicines!C:C,"*"&A42&"*") -> 5
A43: Anti-glaucoma | C43: =COUNTIF(Medicines!C:C,"*"&A43&"*") -> 16
A44: Mydriatic | C44: =COUNTIF(Medicines!C:C,"*"&A44&"*") -> 3
A45: Cycloplegic | C45: =COUNTIF(Medicines!C:C,"*"&A45&"*") -> 3
A46: Lubricant | C46: =COUNTIF(Medicines!C:C,"*"&A46&"*") -> 6
A47: Antihistamine | C47: =COUNTIF(Medicines!C:C,"*"&A47&"*") -> 7
...

Sheet Diseases & Conditions
A1: ID | B1: Disease / Condition | C1: Category | D1: Abbreviation / Synonyms | E1: ICD-10 (indicative) | F1: Colloquial Term (Hindi / Bengali) | G1: Brief Description | H1: Key Symptoms | I1: Usual Management
A2: DIS-001 | B2: Age-related (senile) cataract | C2: Lens / Cataract | D2: Senile cataract, SIC (senile immature cataract) | E2: H25 | F2: Motiyabind (H) / Chokhe chhani (B) | G2: Progressive clouding of the natural lens with age | H2: Gradual painless blurring, glare, faded colours, frequent change of glasses | I2: Spectacles in early stage; Phaco or MSICS with IOL when vision affects daily life
A3: DIS-002 | B3: Nuclear cataract (nuclear sclerosis) | C3: Lens / Cataract | D3: NS, graded NS1–NS4 / LOCS III | E3: H25.1 | F3: Motiyabind (H) / Chhani (B) | G3: Hardening and yellow-brown discolouration of the lens nucleus | H3: Distance blur, myopic shift ("second sight" for near), colour dulling | I3: Phaco / MSICS with IOL
A4: DIS-003 | B4: Cortical cataract | C4: Lens / Cataract | D4: Cortical spokes, cuneiform cataract | E4: H25.0 | F4: Motiyabind (H) / Chhani (B) | G4: Wedge-shaped opacities in the lens cortex | H4: Glare, especially at night; blur | I4: Phaco / MSICS with IOL
A5: DIS-004 | B5: Posterior subcapsular cataract | C5: Lens / Cataract | D5: PSC, PSCC | E5: H25.0 | F5: Motiyabind (H) / Chhani (B) | G5: Opacity just in front of the posterior lens capsule; common with steroids, diabetes | H5: Glare, poor near vision, worse in bright light | I5: Phaco with IOL
A6: DIS-005 | B6: Mature cataract | C6: Lens / Cataract | D6: SMC (senile mature cataract), white cataract | E6: H25.8 | F6: Safed motiya (H) / Paka chhani (B) | G6: Fully opaque lens; fundus not visible | H6: Severe vision loss, hand movements / PL only | I6: Phaco (with trypan blue) or MSICS
A7: DIS-006 | B7: Hypermature / Morgagnian cataract | C7: Lens / Cataract | D7: Morgagnian cataract | E7: H25.2 | F7: Paka motiya (H) / Paka chhani (B) | G7: Liquefied cortex with sinking nucleus; risk of lens-induced glaucoma | H7: Very poor vision; may present with pain and raised IOP | I7: Urgent cataract surgery
A8: DIS-007 | B8: Congenital / developmental cataract | C8: Lens / Cataract | D8: Paediatric cataract, lamellar / zonular cataract | E8: Q12.0 | F8: Bachche ki aankh mein safedi (H) / Bachchar chokhe sada daag (B) | G8: Lens opacity present at birth or developing in childhood | H8: White pupil (leukocoria), squint, nystagmus, poor visual response | I8: Early lensectomy / cataract surgery, amblyopia therapy
A9: DIS-008 | B9: Traumatic cataract | C9: Lens / Cataract | D9: Rosette cataract | E9: H26.1 | F9: Chot se motiya (H) / Aghat theke chhani (B) | G9: Cataract after blunt or penetrating injury | H9: Blur after injury; may have raised IOP | I9: Cataract surgery, treat associated injury
A10: DIS-009 | B10: Complicated cataract | C10: Lens / Cataract | D10: Secondary cataract (to uveitis, RP, high myopia) | E10: H26.2 | G10: Cataract secondary to another eye disease | H10: Blur with history of uveitis etc. | I10: Control inflammation, then surgery with steroid cover
A11: DIS-010 | B11: Steroid-induced cataract | C11: Lens / Cataract | D11: Drug-induced cataract | E11: H26.3 | G11: PSC cataract caused by prolonged steroid use (drops, tablets, inhalers) | H11: Glare, near blur | I11: Taper steroid; cataract surgery
A12: DIS-011 | B12: Diabetic cataract | C12: Lens / Cataract | D12: Snowflake cataract | E12: E11.3 / H28.0 | G12: Cataract occurring earlier / faster in diabetes | H12: Blur, fluctuating refraction | I12: Glycaemic control; surgery with retina evaluation
A13: DIS-012 | B13: Posterior capsular opacification | C13: Lens / Cataract | D13: PCO, after-cataract, "secondary cataract", Elschnig pearls | E13: H26.4 | F13: Jhilli (H) / Porda pora (B) | G13: Clouding of the posterior capsule months/years after cataract surgery | H13: Gradual blur again after successful surgery, glare | I13: Nd:YAG laser capsulotomy
A14: DIS-013 | B14: Pseudophakia | C14: Lens / Cataract | D14: PCIOL in situ, s/p cataract surgery | E14: Z96.1 | F14: Lens lagaya hua (H) / Lens bosano (B) | G14: Status after cataract surgery with IOL implant | H14: — | I14: Routine follow-up, near glasses
A15: DIS-014 | B15: Aphakia | C15: Lens / Cataract | D15: Surgical aphakia | E15: H27.0 | G15: Absence of the natural lens without IOL | H15: Very blurred vision without thick (+10D) glasses | I15: Aphakic glasses, contact lens, secondary IOL (SFIOL / ACIOL)
A16: DIS-015 | B16: Subluxated / dislocated lens | C16: Lens / Cataract | D16: Ectopia lentis (Marfan, trauma, PXF) | E16: H27.1 / Q12.1 | G16: Lens displaced from normal position due to weak zonules | H16: Fluctuating vision, monocular diplopia, iridodonesis | I16: Glasses, lensectomy, CTR / scleral-fixated IOL
A17: DIS-016 | B17: IOL decentration / dislocation | C17: Lens / Cataract | D17: Dropped IOL, IOL subluxation | E17: T85.2 | G17: Implanted lens shifted from centre or dropped into vitreous | H17: Blur, glare, edge effects | I17: IOL repositioning / exchange, vitrectomy
A18: DIS-017 | B18: Primary open-angle glaucoma | C18: Glaucoma | D18: POAG, chronic simple glaucoma | E18: H40.1 | F18: Kala motia (H) / Chokher pressure / Glaucoma (B) | G18: Chronic progressive optic neuropathy with open angle, usually raised IOP | H18: Usually no symptoms until late; gradual peripheral field loss | I18: PG analogue / beta-blocker drops, SLT, trabeculectomy
A19: DIS-018 | B19: Primary angle-closure glaucoma | C19: Glaucoma | D19: PACG, chronic angle closure | E19: H40.2 | F19: Kala motia (H) / Chokher pressure (B) | G19: Glaucoma due to closed/narrow drainage angle | H19: Intermittent haloes, headache, eye ache; may be silent | I19: YAG PI, drops, lens extraction, trabeculectomy
A20: DIS-019 | B20: Acute angle-closure attack | C20: Glaucoma | D20: APAC, acute congestive glaucoma | E20: H40.2 | F20: Aankh mein tez dard aur pressure (H) / Chokhe probol byatha (B) | G20: Sudden closure of the angle with very high IOP — an emergency | H20: Sudden severe pain, red eye, coloured haloes, headache, nausea, vomiting | I20: IV mannitol, oral acetazolamide, pilocarpine, timolol; then YAG PI both eyes
A21: DIS-020 | B21: Primary angle-closure suspect | C21: Glaucoma | D21: PACS, narrow / occludable angles | E21: H40.0 | G21: Narrow angle at risk of closure, no glaucoma yet | H21: None | I21: Prophylactic YAG PI, periodic review
A22: DIS-021 | B22: Normal-tension glaucoma | C22: Glaucoma | D22: NTG, normal-pressure glaucoma (NPG) | E22: H40.1 | G22: Glaucomatous optic neuropathy with IOP in normal range | H22: Silent field loss | I22: Lower IOP by ~30%, check BP / vascular factors
A23: DIS-022 | B23: Ocular hypertension | C23: Glaucoma | D23: OHT | E23: H40.0 | F23: Aankh ka pressure zyada (H) / Chokher pressure beshi (B) | G23: IOP above normal without optic nerve damage | H23: None | I23: Monitor; treat if high risk
A24: DIS-023 | B24: Glaucoma suspect | C24: Glaucoma | D24: GS, suspicious disc | E24: H40.0 | G24: Findings suspicious of glaucoma (large cup, family history) needing monitoring | H24: None | I24: OCT RNFL, perimetry, periodic review
A25: DIS-024 | B25: Pseudoexfoliation glaucoma | C25: Glaucoma | D25: PXF / PXG, capsular glaucoma | E25: H40.1 | G25: Open-angle glaucoma from exfoliative material; higher IOP spikes | H25: Silent; weak zonules at cataract surgery | I25: Drops, SLT, surgery; careful cataract surgery
A26: DIS-025 | B26: Pigmentary glaucoma | C26: Glaucoma | D26: PDS (pigment dispersion syndrome) | E26: H40.1 | G26: Pigment shed from iris blocks trabecular meshwork; young myopes | H26: Blur / haloes after exercise | I26: Drops, laser PI / SLT
A27: DIS-026 | B27: Steroid-induced glaucoma | C27: Glaucoma | D27: Steroid responder | E27: H40.6 | G27: IOP rise from steroid use (drops, creams, tablets) | H27: Silent | I27: Stop / switch steroid, IOP-lowering drops
A28: DIS-027 | B28: Neovascular glaucoma | C28: Glaucoma | D28: NVG, rubeosis iridis | E28: H40.5 | G28: Abnormal new vessels close the angle; after CRVO or PDR | H28: Painful red eye, very high IOP, poor vision | I28: Anti-VEGF, PRP, IOP drops, glaucoma drainage device / CPC
A29: DIS-028 | B29: Phacomorphic glaucoma | C29: Glaucoma | D29: Lens-induced angle closure | E29: H40.5 | G29: Swollen cataractous lens pushes iris forward, closing angle | H29: Acute pain, redness, mature cataract | I29: IOP control then urgent cataract surgery
A30: DIS-029 | B30: Phacolytic glaucoma | C30: Glaucoma | D30: Lens protein glaucoma | E30: H40.5 | G30: Leakage of lens proteins from hypermature cataract blocks outflow | H30: Pain, redness, high IOP, open angle | I30: IOP control, cataract extraction
A31: DIS-030 | B31: Uveitic glaucoma | C31: Glaucoma | D31: Inflammatory glaucoma | E31: H40.4 | G31: Raised IOP from uveitis or its treatment | H31: Pain, redness, blur | I31: Control inflammation, IOP drops (avoid PG in active uveitis)
A32: DIS-031 | B32: Traumatic / angle-recession glaucoma | C32: Glaucoma | D32: Angle recession | E32: H40.3 | G32: Raised IOP after blunt injury damaging the angle | H32: Silent; history of injury | I32: Drops, surgery
A33: DIS-032 | B33: Congenital glaucoma | C33: Glaucoma | D33: Buphthalmos, primary congenital glaucoma (PCG) | E33: Q15.0 | F33: Bachche ki badi aankh (H) / Bachchar boro chokh (B) | G33: Raised IOP in infants from angle maldevelopment | H33: Large hazy cornea, watering, photophobia, blepharospasm | I33: Goniotomy / trabeculotomy + trabeculectomy
A34: DIS-033 | B34: Juvenile open-angle glaucoma | C34: Glaucoma | D34: JOAG | E34: H40.1 | G34: Open-angle glaucoma in age 3–40 years | H34: Often myopic; silent | I34: Drops, early surgery
A35: DIS-034 | B35: Malignant glaucoma | C35: Glaucoma | D35: Aqueous misdirection | E35: H40.8 | G35: Aqueous flows into vitreous, shallowing AC after surgery | H35: Pain, shallow AC, high IOP | I35: Cycloplegics, aqueous suppressants, vitrectomy
A36: DIS-035 | B36: Viral conjunctivitis | C36: Conjunctiva | D36: Adenoviral conjunctivitis, "eye flu", "pink eye" | E36: B30 | F36: Aankh aana (H) / Chokh otha (B) | G36: Contagious viral infection of the conjunctiva | H36: Redness, watering, grittiness, lid swelling, starts in one eye then other | I36: Lubricants, cold compress, hygiene; antibiotic drops to prevent secondary infection; short steroid if membranes / SEIs
A37: DIS-036 | B37: Epidemic keratoconjunctivitis | C37: Conjunctiva | D37: EKC, adenovirus 8/19 | E37: B30.0 | F37: Aankh aana (H) / Chokh otha (B) | G37: Severe adenoviral infection with corneal involvement | H37: Redness, watering, pain, photophobia, blur from SEIs | I37: Lubricants, hygiene, steroid for SEIs / pseudomembrane
A38: DIS-037 | B38: Acute haemorrhagic conjunctivitis | C38: Conjunctiva | D38: AHC, "Apollo conjunctivitis" | E38: B30.3 | F38: Laal aankh (H) / Rokto jomano chokh (B) | G38: Enteroviral conjunctivitis with subconjunctival bleeding; epidemic | H38: Sudden redness with blood spots, watering, pain | I38: Supportive, hygiene
A39: DIS-038 | B39: Bacterial conjunctivitis | C39: Conjunctiva | D39: Mucopurulent conjunctivitis | E39: H10.0 | F39: Aankh mein keechad (H) / Chokhe pichuti (B) | G39: Bacterial infection of the conjunctiva | H39: Redness, sticky yellow-green discharge, lids stuck in the morning | I39: Topical antibiotic drops / ointment
A40: DIS-039 | B40: Allergic conjunctivitis | C40: Conjunctiva | D40: SAC (seasonal), PAC (perennial) | E40: H10.1 | F40: Aankh mein khujli (H) / Chokh chulkano (B) | G40: Allergic reaction of conjunctiva to dust, pollen, etc. | H40: Itching, watering, redness, stringy discharge, both eyes | I40: Antihistamine / mast-cell stabiliser drops, cold compress, avoid rubbing
...

Sheet Symptoms & Complaints
A1: ID | B1: Symptom (Medical Term) | C1: Patient's Words (English) | D1: Colloquial (Hindi / Bengali) | E1: Associated Conditions | F1: Doctor's Follow-up Questions
A2: SYM-001 | B2: Diminution of vision (DOV) | C2: "My vision is getting blurred" | D2: Dhundhla dikhna (H) / Jhapsa dekha (B) | E2: Cataract, refractive error, glaucoma, DR, ARMD | F2: Since when? Gradual or sudden? Distance, near or both? One eye or both? Painful or painless?
A3: SYM-002 | B3: Sudden loss of vision | C3: "I suddenly can't see from one eye" | D3: Achanak dikhna band (H) / Hotat dekhte pachchi na (B) | E3: CRAO, CRVO, RD, VH, optic neuritis, AION | F3: Exact time of onset? Pain? Flashes / floaters? Diabetes / BP / heart disease?
A4: SYM-003 | B4: Gradual painless vision loss | C4: "Vision has been slowly going down for months" | D4: Dheere dheere kam dikhna (H) / Aste aste kom dekha (B) | E4: Cataract, POAG, dry ARMD, refractive error | F4: Glare? Frequent change of glasses? Family history of glaucoma?
A5: SYM-004 | B5: Distance blur | C5: "I can't see the TV / board clearly" | D5: Door ka dhundhla (H) / Dur-er jinish jhapsa (B) | E5: Myopia, astigmatism, nuclear cataract | F5: Do you squint to see? Using glasses? Last check-up?
A6: SYM-005 | B6: Near blur | C6: "I can't read newspaper / mobile" | D6: Paas ka dhundhla (H) / Kacher lekha porte parchhi na (B) | E6: Presbyopia, hypermetropia, PSC cataract | F6: Age? Holding reading material farther away?
A7: SYM-006 | B7: Red eye | C7: "My eye is red" | D7: Aankh laal (H) / Chokh lal (B) | E7: Conjunctivitis, uveitis, keratitis, acute glaucoma, SCH, scleritis | F7: Pain? Discharge? Vision affected? Contact lens use? Injury?
A8: SYM-007 | B8: Watering | C8: "Water keeps coming from my eye" | D8: Aankh se paani aana (H) / Chokh diye jol pora (B) | E8: NLDO, conjunctivitis, FB, dry eye (reflex), trichiasis, ectropion | F8: Constant or intermittent? Sticky? Pressing near nose brings pus?
A9: SYM-008 | B9: Discharge | C9: "Sticky yellow stuff in my eye" | D9: Keechad (H) / Pichuti (B) | E9: Bacterial conjunctivitis, dacryocystitis, corneal ulcer | F9: Colour? Lids stuck in morning? Others at home affected?
A10: SYM-009 | B10: Ropy / stringy discharge | C10: "White thread-like stuff" | D10: Safed dhaagedaar keechad (H) | E10: VKC, allergic conjunctivitis | F10: Itching? Seasonal? History of allergy / asthma?
A11: SYM-010 | B11: Itching | C11: "My eyes are itching a lot" | D11: Aankh mein khujli (H) / Chokh chulkano (B) | E11: Allergic conjunctivitis, VKC, blepharitis, dry eye | F11: Seasonal? Dust / pollen exposure? Rubbing? Allergy history?
A12: SYM-011 | B12: Burning sensation | C12: "My eyes burn" | D12: Aankh mein jalan (H) / Chokh jwala kora (B) | E12: Dry eye, blepharitis, MGD, conjunctivitis, CVS | F12: Worse with screens / AC? Morning or evening?
... A49: SYM-048 | B49: Pain / redness after surgery | C49: "Eye is red and painful few days after operation" | D49: Operation ke baad laal aur dard (H) / Operation-er por lal o byatha (B) | E49: Endophthalmitis, uveitis, raised IOP | F49: Day of surgery? Vision dropping? (EMERGENCY)

Sheet Examination & Tests
A1: ID | B1: Examination / Test | C1: Abbreviation | D1: Type | E1: What It Measures / Purpose | F1: Normal / Reference Value | G1: Common Indications
A2: TST-001 | B2: Visual acuity (distance) | C2: VA, UCVA / BCVA | D2: Examination | E2: Sharpness of distance vision on Snellen / LogMAR chart at 6 m | F2: 6/6 (20/20); LogMAR 0.0 | G2: Every patient — baseline and follow-up
A3: TST-002 | B3: Uncorrected visual acuity | C3: UCVA, UA | D3: Examination | E3: Vision without glasses | F3: 6/6 | G3: Refractive error, pre / post surgery
A4: TST-003 | B4: Best-corrected visual acuity | C4: BCVA, BCDVA | D4: Examination | E4: Vision with best glasses / pinhole | F4: 6/6 | G4: Distinguishes refractive vs pathological loss
A5: TST-004 | B5: Pinhole acuity | C5: PH | D5: Examination | E5: Improvement with pinhole suggests refractive cause | F5: Improves to 6/6 if refractive | G5: Screening for refractive error
A6: TST-005 | B6: Near visual acuity | C6: NVA | D6: Examination | E6: Reading vision at 33–40 cm (Jaeger / N-notation) | F6: N6 / J1 | G6: Presbyopia, near add
A7: TST-006 | B7: Counting fingers / Hand movements / Perception of light | C7: CF, HM, PL, PR, NPL | D7: Examination | E7: Grading of very poor vision | F7: — | G7: Mature cataract, VH, RD, advanced glaucoma
A8: TST-007 | B8: Projection of rays | C8: PR (accurate / inaccurate) | D8: Examination | E8: Checks retinal function in all quadrants in dense cataract | F8: Accurate in all 4 quadrants | G8: Pre-op mature cataract
A9: TST-008 | B9: LogMAR / ETDRS chart | C9: LogMAR | D9: Examination | E9: Standardised acuity measurement | F9: 0.0 | G9: Research, children, retina clinics
A10: TST-009 | B10: Refraction | C10: Ref, Retinoscopy (Ret), Subjective refraction (SR) | D10: Examination | E10: Determines spectacle power | F10: Emmetropia (plano) | G10: Glasses prescription
A11: TST-010 | B11: Autorefraction | C11: AR, ARK (autorefractokeratometer) | D11: Investigation | E11: Objective automated estimate of power and K readings | F11: — | G11: Screening before subjective refraction
A12: TST-011 | B12: Cycloplegic refraction | C12: CR, wet refraction | D12: Examination | E12: Refraction after cyclopentolate / atropine to relax accommodation | F12: — | G12: Children, hypermetropia, squint
... A16: TST-015 | B16: Goldmann applanation tonometry | C16: GAT, AT | D16: Examination | E16: Gold-standard IOP measurement on slit lamp with fluorescein | F16: 10–21 mmHg | G16: Glaucoma diagnosis and monitoring
A17: TST-016 | B17: Schiøtz / iCare / Tono-Pen tonometry | D17: Examination | E17: Alternative IOP devices (indentation / rebound) | F17: 10–21 mmHg | G17: Children, irregular cornea, bedside
A18: TST-017 | B18: Diurnal variation of IOP | C18: DVT / phasing | D18: Investigation | E18: IOP measured at several times of day | F18: Fluctuation < 5 mmHg | G18: NTG, glaucoma suspects
A19: TST-018 | B19: Slit-lamp biomicroscopy | C19: SLE, SLB | D19: Examination | E19: Magnified exam of lids, conjunctiva, cornea, AC, iris, lens | F19: — | G19: Every eye patient
A20: TST-019 | B20: Torchlight examination | D20: Examination | E20: Basic external exam with torch | F20: — | G20: Screening, camps, emergency
A21: TST-020 | B21: Pupil examination / Swinging flashlight test | C21: RAPD, Marcus Gunn pupil | D21: Examination | E21: Pupil reactions; detects afferent defect | F21: PERRLA; no RAPD | G21: Optic neuritis, glaucoma, RD, CRAO
A22: TST-021 | B22: Fundoscopy (direct / indirect) | C22: DO, IDO (indirect ophthalmoscopy) | D22: Examination | E22: View of retina, optic disc, macula, vessels | F22: — | G22: DR, glaucoma, RD, papilloedema
A23: TST-022 | B23: Dilated fundus examination | C23: DFE | D23: Examination | E23: Complete retina exam after dilating drops | F23: — | G23: Diabetics, floaters, myopes
A24: TST-023 | B24: 90D / 78D lens examination | C24: Slit-lamp biomicroscopy of fundus | D24: Examination | E24: Stereo view of disc and macula | F24: C:D ≤ 0.3–0.4 | G24: Glaucoma disc evaluation, macula
A25: TST-024 | B25: Cup-to-disc ratio | C25: CDR, C:D | D25: Finding / measurement | E25: Ratio of optic cup to disc diameter | F25: ≤ 0.3–0.4; asymmetry < 0.2 | G25: Glaucoma
A26: TST-025 | B26: Gonioscopy | C26: Gonio | D26: Examination | E26: Views the drainage angle with a gonio lens (Shaffer / Spaeth grading) | F26: Open, grade 3–4 (Shaffer) | G26: Angle-closure, secondary glaucoma
A27: TST-026 | B27: Van Herick test | D27: Examination | E27: Slit-lamp estimate of peripheral AC depth | F27: Grade 3–4 | G27: Angle-closure screening
A28: TST-027 | B28: Automated perimetry | C28: HFA 24-2 / 30-2 / 10-2, SAP | D28: Investigation | E28: Maps visual field | F28: No defect; reliable indices | G28: Glaucoma, neuro-ophthalmology
A29: TST-028 | B29: Confrontation field test | D29: Examination | E29: Bedside visual field check | F29: Full fields | G29: Neuro screening
A30: TST-029 | B30: Optical coherence tomography | C30: OCT | D30: Investigation | E30: Cross-sectional scan of retina / nerve | F30: CMT ~250 µm (device-dependent) | G30: DME, ARMD, CSCR, macular hole, glaucoma
A31: TST-030 | B31: OCT RNFL / GCC | C31: OCT-RNFL | D31: Investigation | E31: Nerve fibre layer thickness around disc | F31: Green (within normal limits) | G31: Glaucoma diagnosis and progression
A32: TST-031 | B32: OCT angiography | C32: OCTA | D32: Investigation | E32: Dye-free imaging of retinal / choroidal vessels | F32: — | G32: CNVM, DR, vein occlusion
A33: TST-032 | B33: Fundus fluorescein angiography | C33: FFA, FA | D33: Investigation | E33: IV fluorescein dye to show retinal circulation and leakage | F33: No leakage | G33: DR, CNVM, vein occlusion, CSCR
A34: TST-033 | B34: Indocyanine green angiography | C34: ICGA | D34: Investigation | E34: Dye imaging of choroid | F34: — | G34: Polypoidal choroidal vasculopathy, CSCR
A35: TST-034 | B35: Fundus photography | C35: Fundus photo | D35: Investigation | E35: Documentation of retina / disc | F35: — | G35: DR screening, glaucoma documentation
A36: TST-035 | B36: B-scan ultrasonography | C36: USG B-scan | D36: Investigation | E36: Ultrasound of the posterior segment when media is opaque | F36: Attached retina | G36: Mature cataract, VH, RD, IOFB, tumours
A37: TST-036 | B37: A-scan biometry | C37: A-scan, AL | D37: Investigation | E37: Axial length measurement for IOL power | F37: AL ~22–24.5 mm | G37: Pre-cataract surgery
A38: TST-037 | B38: Optical biometry | C38: IOL Master, Lenstar | D38: Investigation | E38: Non-contact axial length, K, ACD for IOL calculation | F38: — | G38: Pre-cataract surgery (IOL power by SRK/T, Barrett etc.)
A39: TST-038 | B39: Keratometry | C39: K1 / K2, K reading | D39: Investigation | E39: Corneal curvature | F39: ~42–46 D | G39: IOL calculation, contact lens fitting, keratoconus
A40: TST-039 | B40: Corneal topography / tomography | C40: Topo, Pentacam | D40: Investigation | E40: Maps corneal shape and thickness | F40: Regular bow-tie; no ectasia | G40: Keratoconus, pre-LASIK, toric IOL planning
A41: TST-040 | B41: Pachymetry | C41: CCT (central corneal thickness) | D41: Investigation | E41: Corneal thickness | F41: ~520–550 µm | G41: Glaucoma (IOP correction), LASIK screening, corneal oedema
... A45: TST-044 | B45: Fluorescein staining | C45: Flu stain | D45: Examination | E45: Shows epithelial defects in cobalt blue light | F45: No staining | G45: Abrasion, ulcer, dry eye, dendrite
A46: TST-045 | B46: Rose bengal / Lissamine green staining | D46: Examination | E46: Stains devitalised cells | F46: — | G46: Dry eye
...

Sheet Clinical Signs
A1: ID | B1: Clinical Sign / Finding | C1: Abbreviation | D1: Structure | E1: Meaning | F1: Suggestive Of
A2: SGN-001 | B2: Conjunctival congestion | C2: Conj. congestion | D2: Conjunctiva | E2: Diffuse redness, more towards fornices | F2: Conjunctivitis
A3: SGN-002 | B3: Ciliary / circumcorneal congestion | C3: CCC, ciliary flush | D3: Conjunctiva / limbus | E3: Redness concentrated around cornea | F3: Uveitis, keratitis, acute glaucoma
A4: SGN-003 | B4: Chemosis | C4: — | D4: Conjunctiva | E4: Swelling / oedema of conjunctiva | F4: Allergy, severe conjunctivitis, orbital cellulitis
A5: SGN-004 | B5: Follicles | C5: — | D5: Palpebral conjunctiva | E5: Small pale lymphoid elevations | F5: Viral, chlamydial conjunctivitis, drug toxicity
A6: SGN-005 | B6: Papillae | C6: — | D6: Palpebral conjunctiva | E6: Red bumps with central vessel | F6: Allergic, bacterial conjunctivitis
A7: SGN-006 | B7: Giant papillae (cobblestone) | C7: — | D7: Upper tarsal conjunctiva | E7: Papillae > 1 mm | F7: VKC, GPC
A8: SGN-007 | B8: Horner–Trantas dots | C8: — | D8: Limbus | E8: White dots at limbus | F8: VKC (limbal type)
A9: SGN-008 | B9: Pseudomembrane / membrane | C9: — | D9: Conjunctiva | E9: Fibrin layer on conjunctiva | F9: EKC, bacterial conjunctivitis
A10: SGN-009 | B10: Preauricular lymphadenopathy | C10: PAN | D10: Face | E10: Enlarged lymph node in front of ear | F10: Viral / chlamydial conjunctivitis
A11: SGN-010 | B11: Subepithelial infiltrates | C11: SEI | D11: Cornea | E11: Round opacities under epithelium | F11: Adenoviral keratoconjunctivitis
A12: SGN-011 | B12: Punctate epithelial erosions | C12: PEE, SPK | D12: Cornea | E12: Fine spots stained with fluorescein | F12: Dry eye, exposure, toxicity, viral
... A60: SGN-059 | B60: Restricted EOM | C60: — | D60: Muscles | E60: Limited eye movement | F60: Nerve palsy, TED, fracture, orbital cellulitis

Sheet Medicines
A1: ID | B1: Generic Name | C1: Drug Class | D1: Dosage Form | E1: Common Strength | F1: Typical Prescription Usage | G1: Indications | H1: Key Cautions / Side Effects | I1: Example Brands (India, indicative)
A2: MED-001 | B2: Moxifloxacin | C2: Antibiotic – fluoroquinolone | D2: Eye drops | E2: 0.5% | F2: 1 drop QID × 7 days; post-op 1 drop 4–6 times/day then taper | G2: Bacterial conjunctivitis, keratitis, post-operative prophylaxis | H2: Transient stinging | I2: Vigamox, Milflox, Moxicip
A3: MED-002 | B3: Gatifloxacin | C3: Antibiotic – fluoroquinolone | D3: Eye drops | E3: 0.3% / 0.5% | F3: 1 drop QID × 7 days | G3: Bacterial conjunctivitis, post-op prophylaxis | H3: Stinging | I3: Zymar, Gatiquin
A4: MED-003 | B4: Ofloxacin | C4: Antibiotic – fluoroquinolone | D4: Eye drops / ointment | E4: 0.3% | F4: 1 drop QID × 5–7 days | G4: Bacterial conjunctivitis, corneal ulcer | H4: Stinging | I4: Exocin, Zenflox
A5: MED-004 | B5: Ciprofloxacin | C5: Antibiotic – fluoroquinolone | D5: Eye drops / ointment | E5: 0.3% | F5: 1 drop QID; ointment HS | G5: Conjunctivitis, corneal ulcer | H5: White corneal precipitates with intensive use | I5: Ciplox
A6: MED-005 | B6: Tobramycin | C6: Antibiotic – aminoglycoside | D6: Eye drops / ointment | E6: 0.3% | F6: 1 drop QID × 7 days | G6: Bacterial conjunctivitis, blepharitis | H6: Epithelial toxicity with prolonged use | I6: Tobrex, Toba
A7: MED-006 | B7: Gentamicin | C7: Antibiotic – aminoglycoside | D7: Eye drops | E7: 0.3% | F7: 1 drop QID | G7: Bacterial conjunctivitis | H7: Epithelial toxicity | I7: Genticyn
A8: MED-007 | B8: Chloramphenicol | C8: Antibiotic | D8: Eye drops / ointment / applicaps | E8: 0.5% drops, 1% ointment | F8: 1 drop QID; ointment HS | G8: Conjunctivitis, stye, post-FB removal | H8: Rare blood dyscrasia (theoretical) | I8: Chloromycetin Applicaps
A9: MED-008 | B9: Azithromycin (topical) | C9: Antibiotic – macrolide | D9: Eye drops | E9: 1% | F9: 1 drop BD × 2 days then OD × 5 days | G9: Bacterial conjunctivitis, blepharitis / MGD | H9: Blurring, irritation | I9: AzaSite
A10: MED-009 | B10: Fusidic acid | C10: Antibiotic | D10: Viscous drops / gel | E10: 1% | F10: 1 drop BD × 7 days | G10: Conjunctivitis, stye, children | H10: Stinging | I10: Fucithalmic
A11: MED-010 | B11: Fortified cefazolin | C11: Antibiotic – cephalosporin (compounded) | D11: Eye drops | E11: 5% (50 mg/ml) | F11: 1 drop hourly (loading), then taper | G11: Bacterial corneal ulcer (Gram-positive) | H11: Prepared in pharmacy; refrigerate; short shelf life | I11: Hospital-prepared
A12: MED-011 | B12: Fortified tobramycin | C12: Antibiotic – aminoglycoside (compounded) | D12: Eye drops | E12: 1.3% | F12: 1 drop hourly, alternating with cefazolin | G12: Bacterial corneal ulcer (Gram-negative) | H12: Epithelial toxicity | I12: Hospital-prepared
... A117: MED-116 | B117: Silicone oil | C117: Vitreous tamponade | D117: Intravitreal | E117: 1000 / 5000 cSt | F117: Intra-operative; removal after 3–6 months | G117: Complex RD, PVR | H117: Raised IOP, cataract, emulsification | I117: —

Sheet Procedures & Surgery
A1: ID | B1: Procedure / Surgery | C1: Abbreviation | D1: Category | E1: Description | F1: Indication | G1: Anaesthesia / Setting
A2: PRC-001 | B2: Phacoemulsification with IOL | C2: Phaco, PE + PCIOL | D2: Cataract surgery | E2: Ultrasound breaks lens through 2.2–2.8 mm incision; foldable IOL in bag; usually stitchless | F2: Cataract | G2: Topical / peribulbar; day care
A3: PRC-002 | B3: Manual small-incision cataract surgery | C3: MSICS, SICS | D3: Cataract surgery | E3: Sutureless scleral tunnel, nucleus delivered whole; rigid PMMA or foldable IOL | F3: Cataract (especially mature / camps) | G3: Peribulbar; day care
A4: PRC-003 | B4: Extracapsular cataract extraction | C4: ECCE | D4: Cataract surgery | E4: Large incision with sutures; nucleus expressed | F4: Cataract (older technique) | G4: Peribulbar
A5: PRC-004 | B5: Femtosecond laser-assisted cataract surgery | C5: FLACS | D5: Cataract surgery | E5: Laser performs capsulotomy and lens fragmentation | F5: Cataract (premium option) | G5: Topical
A6: PRC-005 | B6: Monofocal IOL | D6: IOL type | E6: Clear vision at one distance (usually distance); reading glasses needed | F6: Standard cataract surgery | G6: —
A7: PRC-006 | B7: Multifocal / Trifocal IOL | D7: IOL type | E7: Multiple focal points for distance, intermediate and near | F7: Spectacle independence | G7: —
A8: PRC-007 | B8: Extended depth of focus IOL | C8: EDOF IOL | D8: IOL type | E8: Continuous range from distance to intermediate | F8: Spectacle independence for computer use | G8: —
A9: PRC-008 | B9: Toric IOL | D9: IOL type | E9: Corrects corneal astigmatism; aligned to axis | F9: Cataract with astigmatism > ~1 D | G9: —
A10: PRC-009 | B10: Hydrophobic / Hydrophilic acrylic IOL | D10: IOL material | E10: Foldable IOL materials; hydrophobic has lower PCO rate | F10: Cataract surgery | G10: —
A11: PRC-010 | B11: Rigid PMMA IOL | C11: PMMA | D11: IOL material | E11: Non-foldable economical IOL | F11: MSICS | G11: —
A12: PRC-011 | B12: Anterior chamber IOL | C12: ACIOL | D12: IOL type | E12: IOL placed in front of iris | F12: Inadequate capsule support | G12: —
A13: PRC-012 | B13: Scleral-fixated / Glued IOL | C13: SFIOL, glued IOL | D13: IOL surgery | E13: IOL fixed to sclera with sutures or fibrin glue | F13: Aphakia without capsule support | G13: Peribulbar
A14: PRC-013 | B14: Iris-claw IOL | D14: IOL surgery | E14: IOL clipped to iris | F14: Aphakia | G14: Peribulbar
A15: PRC-014 | B15: Nd:YAG laser capsulotomy | C15: YAG cap | D15: Laser | E15: Laser opening in opacified posterior capsule | F15: PCO | G15: Topical; OPD, 5 minutes
A16: PRC-015 | B16: Nd:YAG laser peripheral iridotomy | C16: YAG PI, LPI | D16: Laser | E16: Small hole in peripheral iris to open angle | F16: Angle closure, PACS | G16: Topical; OPD
A17: PRC-016 | B17: Selective laser trabeculoplasty | C17: SLT | D17: Laser | E17: Laser to trabecular meshwork to increase outflow | F17: POAG, OHT | G17: Topical; OPD
A18: PRC-017 | B18: Trabeculectomy | C18: Trab, filtering surgery | D18: Glaucoma surgery | E18: Creates new drainage channel under conjunctiva (bleb), often with MMC | F18: Uncontrolled glaucoma | G18: Peribulbar
A19: PRC-018 | B19: Glaucoma drainage device | C19: Ahmed / Aurolab valve, tube surgery | D19: Glaucoma surgery | E19: Tube shunts aqueous to plate under conjunctiva | F19: Refractory / NVG / failed trab | G19: Peribulbar
A20: PRC-019 | B20: Minimally invasive glaucoma surgery | C20: MIGS (iStent, Kahook dual blade, GATT) | D20: Glaucoma surgery | E20: Small-incision angle procedures, often combined with phaco | F20: Mild–moderate glaucoma | G20: Topical
A21: PRC-020 | B21: Cyclophotocoagulation | C21: CPC, diode / micropulse CPC | D21: Glaucoma laser | E21: Laser to ciliary body to reduce aqueous production | F21: Refractory / painful blind eye | G21: Peribulbar
A22: PRC-021 | B22: Goniotomy / Trabeculotomy | C22: — | D22: Paediatric glaucoma surgery | E22: Opens angle in congenital glaucoma | F22: Congenital glaucoma | G22: General anaesthesia
A23: PRC-022 | B23: Laser-assisted in situ keratomileusis | C23: LASIK, Femto-LASIK, Contoura | D23: Refractive surgery | E23: Flap created, excimer laser reshapes cornea | F23: Myopia, hypermetropia, astigmatism | G23: Topical; day care
A24: PRC-023 | B24: Photorefractive keratectomy | C24: PRK, Trans-PRK | D24: Refractive surgery | E24: Surface ablation without flap | F24: Thin cornea, low myopia | G24: Topical
A25: PRC-024 | B25: Small-incision lenticule extraction | C25: SMILE | D25: Refractive surgery | E25: Femtosecond laser lenticule removed via small incision | F25: Myopia, astigmatism | G25: Topical
A26: PRC-025 | B26: Implantable collamer lens | C26: ICL, phakic IOL | D26: Refractive surgery | E26: Lens placed in front of natural lens | F26: High myopia, thin cornea | G26: Topical
... A46: PRC-045 | B46: Probing and syringing | C46: — | D46: Lacrimal procedure | E46: Probe opens congenital blocked duct | F46: Congenital NLDO | G46: Short GA
A47: PRC-046 | B47: Punctal plugs / punctal cautery | D47: Lacrimal procedure | E47: Blocks tear drainage to retain tears | F47: Severe dry eye | G47: OPD
A48: PRC-047 | B48: Panretinal photocoagulation | C48: PRP | D48: Retina laser | E48: Laser to peripheral retina to regress new vessels | F48: PDR, ischaemic CRVO, NVG | G48: Topical; OPD (multiple sittings)
A49: PRC-048 | B49: Focal / grid laser | C49: Macular laser | D49: Retina laser | E49: Laser to leaking microaneurysms | F49: DME, BRVO | G49: Topical; OPD
A50: PRC-049 | B50: Laser barrage / retinopexy | C50: Barrage laser | D50: Retina laser | E50: Laser around retinal tear / lattice | F50: Retinal tear, lattice | G50: Topical; OPD
A51: PRC-050 | B51: Intravitreal injection | C51: IVI (anti-VEGF / steroid) | D51: Retina procedure | E51: Drug injected into vitreous 3.5–4 mm from limbus | F51: Wet AMD, DME, RVO, endophthalmitis | G51: Topical; OT / clean room
A52: PRC-051 | B52: Pars plana vitrectomy | C52: PPV (23G / 25G) | D52: Retina surgery | E52: Removal of vitreous gel with instruments | F52: RD, VH, macular hole, ERM, endophthalmitis, dropped nucleus | G52: Peribulbar / GA
A53: PRC-052 | B53: Scleral buckle | C53: SB, SFR (scleral buckling) | D53: Retina surgery | E53: Silicone band sutured on sclera to support retina | F53: Rhegmatogenous RD (young, phakic) | G53: Peribulbar / GA
A54: PRC-053 | B54: Pneumatic retinopexy | C54: — | D54: Retina procedure | E54: Gas bubble injection + positioning + cryo / laser | F54: Selected superior RD | G54: Topical; OPD
A55: PRC-054 | B55: Silicone oil removal | C55: SOR | D55: Retina surgery | E55: Removal of silicone oil tamponade | F55: After PPV | G55: Peribulbar
A56: PRC-055 | B56: Photodynamic therapy | C56: PDT (verteporfin) | D56: Retina laser | E56: Light-activated drug closes abnormal vessels | F56: Chronic CSCR, PCV | G56: OPD
A57: PRC-056 | B57: Squint surgery | C57: Recession / resection of EOM | D57: Strabismus surgery | E57: Adjusting extraocular muscles to align eyes | F57: Esotropia, exotropia | G57: GA (children) / local
A58: PRC-057 | B58: Occlusion therapy | C58: Patching | D58: Paediatric treatment | E58: Patching the better eye for set hours daily | F58: Amblyopia | G58: Home
A59: PRC-058 | B59: Enucleation | C59: — | D59: Orbit surgery | E59: Removal of the entire eyeball | F59: Retinoblastoma, painful blind eye | G59: GA
...

Sheet Optical & Refraction
A1: ID | B1: Term | C1: Abbreviation / Notation | D1: Meaning | E1: Example (as written)
A2: OPT-001 | B2: Right eye | C2: RE / OD (oculus dexter) | D2: Right eye in prescriptions | E2: RE: -1.50 DS
A3: OPT-002 | B3: Left eye | C3: LE / OS (oculus sinister) | D3: Left eye | E3: LE: -1.75 DS
A4: OPT-003 | B4: Both eyes | C4: BE / OU (oculus uterque) | D4: Both eyes | E4: BE: Add +2.00 DS
A5: OPT-004 | B5: Spherical power | C5: Sph / DS (dioptre sphere) | D5: Power for myopia (–) or hypermetropia (+) | E5: -2.00 DS
A6: OPT-005 | B6: Cylindrical power | C6: Cyl / DC (dioptre cylinder) | D6: Power correcting astigmatism | E6: -0.75 DC
A7: OPT-006 | B7: Axis | C7: Ax | D7: Orientation of cylinder, 0–180° | E7: -0.75 DC × 180°
A8: OPT-007 | B8: Addition | C8: Add | D8: Extra plus power for near (presbyopia) | E8: Add +2.50 DS
A9: OPT-008 | B9: Dioptre | C9: D | D9: Unit of lens power (1 / focal length in metres) | E9: +1.00 D
A10: OPT-009 | B10: Plano | C10: PL / ∞ | D10: Zero power | E10: Plano / -0.50 × 90
A11: OPT-010 | B11: Spherical equivalent | C11: SE | D11: Sphere + ½ cylinder | E11: -2.00 / -1.00 × 180 → SE -2.50
A12: OPT-011 | B12: Prism dioptre | C12: PD / Δ | D12: Unit of prism power / squint measurement | E12: 2Δ base-in
... A17: OPT-016 | B17: Near notation | C17: N6, N8, N10, N12, N18, N36 / J1–J6 | D17: Near reading acuity | E17: Near vision N6 with add
A18: OPT-017 | B18: Emmetropia | D18: No refractive error | E18: Emmetropic both eyes
A19: OPT-018 | B19: Unifocal / single-vision lenses | C19: SV | D19: One power throughout lens | E19: Distance glasses only
A20: OPT-019 | B20: Bifocal lenses | C20: Kryptok / D-segment / executive | D20: Two powers (distance + near) with visible line | E20: Bifocal D-top
A21: OPT-020 | B21: Progressive addition lenses | C21: PAL, progressives | D21: Gradual power change: distance → intermediate → near, no line | E21: Advised PAL
A22: OPT-021 | B22: Anti-reflective coating | C22: ARC | D22: Reduces glare and reflections | E22: ARC, hard coat
A23: OPT-022 | B23: Blue-cut lens | D23: Filters blue light (screen users) | E23: Blue-cut ARC
A24: OPT-023 | B24: Photochromic lens | C24: Photogrey / transitions | D24: Darkens in sunlight | E24: Photochromic for outdoor
A25: OPT-024 | B25: Polycarbonate lens | D25: Impact-resistant; children / sports | E25: Polycarbonate for child
A26: OPT-025 | B26: High-index lens | C26: 1.67 / 1.74 | D26: Thinner lenses for high power | E26: 1.67 index for -8.00
A27: OPT-026 | B27: Myopia control spectacle lens | C27: DIMS / HAL (e.g., defocus lenses) | D27: Slows myopia progression in children | E27: DIMS lenses prescribed
A28: OPT-027 | B28: Soft contact lens | C28: SCL | D28: Flexible lenses (daily / monthly) | E28: Monthly disposable SCL
A29: OPT-028 | B29: Rigid gas-permeable lens | C29: RGP | D29: Rigid lens for keratoconus / irregular cornea | E29: RGP trial for KC
A30: OPT-029 | B30: Scleral lens | D30: Large rigid lens vaulting over cornea | E30: Scleral lens for advanced KC
A31: OPT-030 | B31: Toric contact lens | D31: Contact lens correcting astigmatism | E31: Toric SCL -2.00 / -1.25 × 180
A32: OPT-031 | B32: Orthokeratology | C32: Ortho-K | D32: Overnight rigid lens to reshape cornea temporarily | E32: Ortho-K for myopia control
A33: OPT-032 | B33: Low-vision aids | C33: LVA | D33: Magnifiers, telescopes, CCTV | E33: Hand magnifier 4×
A34: OPT-033 | B34: Accommodation | D34: Eye's ability to focus for near | E34: Reduced with age (presbyopia)
A35: OPT-034 | B35: Anisometropia | D35: Difference in power between eyes | E35: RE -1.00 / LE -4.00
A36: OPT-035 | B36: Aniseikonia | D36: Difference in image size between eyes | E36: After unilateral aphakia
A37: OPT-036 | B37: Refractive surprise / residual refractive error | D37: Unexpected power after cataract / refractive surgery | E37: Residual -1.00 after phaco
A38: OPT-037 | B38: Glass prescription validity | D38: Recommended re-check interval | E38: Review after 1 year (children 6 months)

Sheet Rx Abbreviations
A1: ID | B1: Abbreviation | C1: Full Form | D1: Context | E1: Example Usage
A2: ABR-001 | B2: c/o | C2: Complains of | D2: History | E2: c/o DOV RE × 6 months
A3: ABR-002 | B3: DOV | C3: Diminution of vision | D3: History | E3: Gradual painless DOV BE
A4: ABR-003 | B4: H/o | C4: History of | D4: History | E4: H/o trauma LE with stick
A5: ABR-004 | B5: k/c/o | C5: Known case of | D5: History | E5: k/c/o DM, HTN
A6: ABR-005 | B6: DM | C6: Diabetes mellitus | D6: Systemic history | E6: DM × 10 yrs on OHA
A7: ABR-006 | B7: HTN | C7: Hypertension | D7: Systemic history | E7: HTN on medication
A8: ABR-007 | B8: BA / COPD | C8: Bronchial asthma / chronic obstructive pulmonary disease | D8: Systemic history | E8: Timolol contraindicated in BA
A9: ABR-008 | B9: s/p | C9: Status post | D9: History | E9: s/p phaco + PCIOL RE (2024)
A10: ABR-009 | B10: POD | C10: Post-operative day | D10: Follow-up | E10: POD 1: VA 6/12, AC quiet
A11: ABR-010 | B11: RE / LE / BE | C11: Right / left / both eyes | D11: All notes | E11: BE allergic conjunctivitis
A12: ABR-011 | B12: OD / OS / OU | C12: Right eye / left eye / both eyes (Latin) | D12: All notes | E12: Caution: "OD" is also used for "once daily" – write RE / LE to avoid errors
... A90: ABR-089 | B90: Cycloplegia | C90: Paralysis of accommodation | D90: Refraction | E90: Under cycloplegia: +3.00 DS BE

Sheet Counselling & Advice
A1: ID | B1: Context | C1: Instruction / Phrase Used with Patient | D1: Explanation / Why
A2: CNS-001 | B2: Eye drop technique | C2: "Tilt head back, pull lower lid down, put one drop, close eyes gently for 1–2 minutes." | D2: One drop is enough; extra drops spill out
A3: CNS-002 | B3: Eye drop technique | C3: "Press the inner corner of the eye (near the nose) for 1–2 minutes after the drop." | D3: Punctal occlusion – reduces systemic absorption (important for timolol) and improves effect
A4: CNS-003 | B4: Eye drop technique | C4: "Keep a 5-minute gap between two different eye drops." | D4: Prevents washing out of the first drop
A5: CNS-004 | B5: Eye drop technique | C5: "Use drops before ointment; apply ointment last / at bedtime." | D5: Ointment blocks absorption of drops
A6: CNS-005 | B6: Eye drop technique | C6: "Shake the bottle well before use." | D6: For suspensions – prednisolone acetate, loteprednol, brinzolamide, natamycin
A7: CNS-006 | B7: Eye drop technique | C7: "Do not touch the bottle tip to the eye or fingers." | D7: Prevents contamination
A8: CNS-007 | B8: Eye drop technique | C8: "Discard the bottle one month after opening." | D8: Contamination risk (unless labelled otherwise)
A9: CNS-008 | B9: Eye drop technique | C9: "Keep latanoprost bottle in the fridge before opening." | D9: Storage requirement for some PG analogues
A10: CNS-009 | B10: Eye drop technique | C10: "Remove contact lenses before putting drops; reinsert after 15 minutes." | D10: Preservatives absorbed by soft lenses
A11: CNS-010 | B11: Steroid drops | C11: "Do not stop the steroid drops suddenly; reduce as per the taper chart." | D11: Prevents rebound inflammation
A12: CNS-011 | B12: Steroid drops | C12: "Do not use steroid drops without doctor's advice; they can cause glaucoma and cataract." | D12: Common misuse of OTC steroid drops in India
... A55: CNS-054 | B55: Follow-up | C55: "Bring all your eye drops and old prescriptions on the next visit." | D55: Medication reconciliation

Sheet Eye Anatomy
A1: ID | B1: Structure | C1: Region | D1: Function | E1: Related Conditions
A2: ANT-001 | B2: Cornea | C2: Anterior segment | D2: Clear front window; main focusing surface (~43 D) | E2: Keratitis, ulcer, keratoconus, abrasion, dystrophy
A3: ANT-002 | B3: Corneal epithelium | C3: Cornea | D3: Outer protective layer; regenerates quickly | E3: Abrasion, PEE, dendritic ulcer
A4: ANT-003 | B4: Bowman's layer | C4: Cornea | D4: Acellular layer beneath epithelium | E4: Scarring
A5: ANT-004 | B5: Corneal stroma | C5: Cornea | D5: Thick collagen layer, 90% of thickness | E5: Scars, fungal ulcer, keratoconus
A6: ANT-005 | B6: Descemet's membrane | C6: Cornea | D6: Basement membrane of endothelium | E6: DM folds, DMEK
A7: ANT-006 | B7: Corneal endothelium | C7: Cornea | D7: Pumps fluid to keep cornea clear; does not regenerate | E7: Fuchs, PBK, corneal oedema
A8: ANT-007 | B8: Limbus | C8: Anterior segment | D8: Junction of cornea and sclera; stem cells | E8: VKC (Trantas dots), OSSN, limbal stem cell deficiency
A9: ANT-008 | B9: Conjunctiva (bulbar / palpebral / fornix) | C9: Ocular surface | D9: Thin membrane covering sclera and inner lids | E9: Conjunctivitis, pterygium, SCH
A10: ANT-009 | B10: Sclera | C10: Outer coat | D10: White tough outer wall | E10: Scleritis, scleral thinning
A11: ANT-010 | B11: Episclera | C11: Outer coat | D11: Thin vascular tissue over sclera | E11: Episcleritis
A12: ANT-011 | B12: Tear film (lipid / aqueous / mucin) | C12: Ocular surface | D12: Lubricates and nourishes cornea | E12: Dry eye, MGD
... A51: ANT-050 | B51: Facial nerve (VII) | C51: Neuro | D51: Supplies orbicularis (lid closure) | E51: Bell's palsy, exposure keratopathy

Sheet Conversation Scenarios
A1: ID | B1: Scenario | C1: Typical Chief Complaint (Patient) | D1: Key History Questions (Doctor) | E1: Examination / Tests | F1: Diagnosis Written As | G1: Sample Prescription / Plan | H1: Advice / Follow-up
A2: SCN-001 | B2: Senile cataract | C2: "Doctor, everything looks hazy for the last one year; glasses aren't helping." | D2: Duration, glare at night, frequent power change, DM / HTN, blood thinners | E2: VA with PH, SLE (lens grading), IOP, DFE / B-scan, biometry, syringing, pre-op bloods | F2: Immature senile cataract (NS3) RE; early cataract LE | G2: Plan: Phaco + foldable PCIOL RE. Pre-op: E/D Moxifloxacin QID × 3 days. Post-op: E/D Moxifloxacin + Dexamethasone 6×/day tapering over 4 weeks; E/D Nepafenac TID × 4 weeks | H2: IOL options and package counselling; post-op care; glasses after 1 month
A3: SCN-002 | B3: Post-cataract review (POD 1) | C3: "I can see better, slight grittiness." | D3: Pain, redness, discharge | E3: VA, SLE (wound, AC cells, cornea, IOL position), IOP | F3: Pseudophakia RE, POD 1, quiet AC | G3: Continue steroid–antibiotic taper; lubricants QID | H3: Shield at night; no water in eye; review at 1 week and 1 month
A4: SCN-003 | B4: Posterior capsular opacification | C4: "After cataract operation I saw well, but now it's blurry again." | D4: Time since surgery, glare | E4: VA, SLE (PCO grading), IOP, DFE | F4: PCO RE (pseudophakic) | G4: Nd:YAG capsulotomy RE; E/D Loteprednol QID × 5 days; Apraclonidine pre / post laser | H4: Floaters may appear; review 1 week with IOP
A5: SCN-004 | B5: Primary open-angle glaucoma | C5: "No problem, came for spectacle check." (IOP found high) | D5: Family history, steroid use, asthma / heart disease, previous IOP | E5: VA, GAT, gonioscopy (open), 90D disc (C:D 0.7), HFA 24-2, OCT RNFL, CCT | F5: POAG BE (moderate) | G5: E/D Latanoprost 0.005% HS BE; add E/D Timolol 0.5% BD if target not reached | H5: Lifelong drops; punctal occlusion; IOP every 3 months; fields every 6 months; screen family
A6: SCN-005 | B6: Acute angle-closure attack | C6: "Severe pain in right eye with headache and vomiting since last night; seeing rainbow rings." | D6: Onset, haloes, previous attacks, recent dilation / drugs | E6: VA, IOP (e.g., 56 mmHg), SLE (corneal oedema, shallow AC, mid-dilated pupil), gonioscopy fellow eye | F6: Acute primary angle-closure RE; PACS LE | G6: Inj Mannitol 20% IV stat; Tab Acetazolamide 500 mg stat then 250 mg QID; E/D Timolol 0.5% stat; E/D Pilocarpine 2% after IOP falls; E/D Prednisolone acetate QID | H6: YAG PI both eyes once cornea clears; urgent follow-up
A7: SCN-006 | B7: Viral conjunctivitis | C7: "Both eyes red, watering and gritty for 3 days; family members also have it." | D7: Contacts, fever / cold, discharge type, vision | E7: VA, SLE (follicles, SEIs, pseudomembrane), preauricular node | F7: Acute viral (adenoviral) conjunctivitis BE | G7: E/D Moxifloxacin QID × 5 days (prophylaxis); E/D CMC 0.5% 6×/day; cold compress; E/D Loteprednol if SEIs | H7: Hand hygiene; separate towel; stay home 5–7 days; review if vision drops
A8: SCN-007 | B8: Bacterial conjunctivitis | C8: "Yellow discharge, eyelids stuck in the morning." | D8: Duration, contact lens use | E8: VA, SLE (papillae, mucopurulent discharge), cornea clear | F8: Acute bacterial conjunctivitis LE | G8: E/D Tobramycin 0.3% QID × 7 days; E/O Chloramphenicol HS | H8: Clean discharge with boiled cooled water; hygiene
A9: SCN-008 | B9: Allergic conjunctivitis | C9: "Eyes itch badly, especially in spring and when dusting." | D9: Seasonality, atopy (asthma, eczema), rubbing | E9: SLE (papillae, chemosis, stringy mucus) | F9: Seasonal allergic conjunctivitis BE | G9: E/D Olopatadine 0.1% BD × 4–6 weeks; E/D CMC QID; E/D FML 0.1% BD × 1 week if severe | H9: Avoid rubbing; cold compress; sunglasses
A10: SCN-009 | B10: Vernal keratoconjunctivitis (child) | C10: "My son keeps rubbing his eyes and has thick white discharge every summer." | D10: Age, seasonality, allergy history, steroid misuse | E10: SLE: giant papillae, Trantas dots, shield ulcer; IOP | F10: VKC (mixed type) BE | G10: E/D Olopatadine 0.2% OD; E/D Cyclosporine 0.05% BD; short pulse of E/D Loteprednol QID × 1 week; E/D CMC | H10: Long-term follow-up; monitor IOP on steroids; avoid rubbing
A11: SCN-010 | B11: Dry eye / computer vision syndrome | C11: "Eyes burn and feel tired after office work." | D11: Screen hours, AC environment, contact lens, medications | E11: Schirmer's, TBUT, fluorescein staining, lid margin exam | F11: Dry eye disease with MGD BE | G11: E/D CMC 0.5% QID; E/G Carbomer HS; warm compress + lid hygiene BD; Cap Omega-3 × 3 months | H11: 20-20-20 rule; blinking; screen ergonomics
A12: SCN-011 | B12: Stye | C12: "Painful swelling on the edge of upper eyelid." | D12: Duration, recurrences, blood sugar | E12: Lid exam: localised tender swelling, pus point | F12: External hordeolum RE upper lid | G12: E/O Chloramphenicol BD–TID; hot fomentation QID; Tab Paracetamol SOS | H12: Don't squeeze; check sugar if recurrent
... A29: SCN-028 | B29: Optic neuritis | C29: "Vision in right eye went blurry over 2 days, pain when I move the eye." | D29: Age, previous episodes, neurological symptoms | E29: VA, RAPD, colour vision (Ishihara), fundus, VEP, MRI brain | F29: Optic neuritis RE (retrobulbar) | G29: Inj Methylprednisolone 1 g IV × 3 days, then oral prednisolone taper | H29: Neurology referral (MS workup); recovery over weeks
